<?xml version="1.0"?>
<robot xmlns:xacro="http://ros.org/wiki/xacro" name="ur10e_mod">

  <!-- Args -->
  <xacro:arg name="name" default="ur10e_mod"/>
  <xacro:arg name="tf_prefix" default=""/>
  <xacro:arg name="ur_type" default="ur10e"/>
  <xacro:arg name="joint_limit_params" default="$(find ur10e_mod)/config/joint_limits.yaml"/>
  <xacro:arg name="kinematics_params" default="$(find ur10e_mod)/config/default_kinematics.yaml"/>
  <xacro:arg name="physical_params" default="$(find ur10e_mod)/config/physical_parameters.yaml"/>
  <xacro:arg name="visual_params" default="$(find ur10e_mod)/config/visual_parameters.yaml"/>
  <xacro:arg name="safety_limits" default="false"/>
  <xacro:arg name="safety_pos_margin" default="0.15"/>
  <xacro:arg name="safety_k_position" default="20"/>
  <xacro:arg name="transmission_hw_interface" default=""/>
  <xacro:arg name="simulation_controllers" default=""/>
  <xacro:arg name="ros_namespace" default=""/>

  <!-- Includes -->
  <xacro:include filename="$(find ur_description)/urdf/ur_macro.xacro"/>
  <xacro:include filename="$(find ur10e_mod)/urdf/ur10e_mod_gz.ros2_control.xacro"/>

  <!-- World -->
  <link name="world"/>

  <link name="base_prismatic_link">
    <inertial>
      <mass value="10.0"/>
      <inertia ixx="0.1" ixy="0.0" ixz="0.0" iyy="0.1" iyz="0.0" izz="0.1"/>
    </inertial>
  </link>
  
  <joint name="base_prismatic_joint" type="fixed">
    <parent link="world"/>
    <child link="base_prismatic_link"/>
  </joint>

  <!-- Prismatic Lift -->
  <link name="z_lift_link">
    <visual>
      <geometry>
        <cylinder length="0.05" radius="0.1"/>
      </geometry>
      <origin rpy="0 0 0" xyz="0 0 0.025"/>
    </visual>
    <collision>
      <geometry>
        <cylinder length="0.05" radius="0.1"/>
      </geometry>
      <origin rpy="0 0 0" xyz="0 0 0.025"/>
    </collision>
    <inertial>
      <mass value="1.0"/>
      <origin rpy="0 0 0" xyz="0 0 0.025"/>
      <inertia ixx="0.01" ixy="0.0" ixz="0.0" iyy="0.01" iyz="0.0" izz="0.01"/>
    </inertial>
  </link>

  <joint name="z_lift_joint" type="prismatic">
    <parent link="base_prismatic_link"/>
    <child link="z_lift_link"/>
    <origin xyz="0 0 0" rpy="0 0 0"/>
    <axis xyz="0 0 1"/>
    <limit lower="0.0" upper="1.0" effort="10000" velocity="1.0"/>
  </joint>

  <!-- Arm -->
  <xacro:ur_robot
    name="$(arg name)"
    tf_prefix="$(arg tf_prefix)"
    parent="z_lift_link"
    joint_limits_parameters_file="$(arg joint_limit_params)"
    kinematics_parameters_file="$(arg kinematics_params)"
    physical_parameters_file="$(arg physical_params)"
    visual_parameters_file="$(arg visual_params)"
    safety_limits="$(arg safety_limits)"
    safety_pos_margin="$(arg safety_pos_margin)"
    safety_k_position="$(arg safety_k_position)"
    force_abs_paths="true">
    <origin xyz="0 0 0" rpy="0 0 0"/>
  </xacro:ur_robot>

  <!-- Gazebo Plugin -->
  <gazebo reference="world">
  </gazebo>
  <gazebo>
    <plugin filename="gz_ros2_control-system" name="gz_ros2_control::GazeboSimROS2ControlPlugin">
      <parameters>$(find ur10e_mod)/config/ur_controllers_with_z_lift.yaml</parameters>
      <ros>
        <namespace>$(arg ros_namespace)</namespace>
      </ros>
    </plugin>
  </gazebo>

  <!-- ros2_control block -->
  <xacro:ur_ros2_control
    name="$(arg name)"
    tf_prefix="$(arg tf_prefix)"
    transmission_hw_interface="$(arg transmission_hw_interface)"
    initial_positions="${dict(z_lift_joint=0.5,shoulder_pan_joint=0.0,shoulder_lift_joint=-1.57,elbow_joint=0.0,wrist_1_joint=-1.57,wrist_2_joint=0.0,wrist_3_joint=0.0)}"
  />

</robot>