<?xml version="1.0"?>
<robot xmlns:xacro="http://ros.org/wiki/xacro" name="ur10e_mod">

  <!-- Args -->
  <xacro:arg name="name" default="ur10e_mod"/>
  <xacro:arg name="tf_prefix" default=""/>
  <xacro:arg name="ur_type" default="ur10e"/>
  <xacro:arg name="joint_limit_params" default="$(find ur_description)/config/$(arg ur_type)/joint_limits.yaml"/>
  <xacro:arg name="kinematics_params" default="$(find ur_description)/config/$(arg ur_type)/default_kinematics.yaml"/>
  <xacro:arg name="physical_params" default="$(find ur_description)/config/$(arg ur_type)/physical_parameters.yaml"/>
  <xacro:arg name="visual_params" default="$(find ur_description)/config/$(arg ur_type)/visual_parameters.yaml"/>
  <xacro:arg name="safety_limits" default="false"/>
  <xacro:arg name="safety_pos_margin" default="0.15"/>
  <xacro:arg name="safety_k_position" default="20"/>
  <xacro:arg name="transmission_hw_interface" default=""/>
  <xacro:arg name="simulation_controllers" default=""/>
  <xacro:arg name="ros_namespace" default=""/>

  <!-- Includes -->
  <xacro:include filename="$(find ur_description)/urdf/ur_macro.xacro"/>
  <xacro:include filename="$(find ur10e_mod)/urdf/ur10e_mod_gz.ros2_control.xacro"/>

  <!-- World -->
  <link name="world"/>

  <!-- Prismatic Lift -->
  <link name="z_lift_link">
    <visual>
        <geometry>
        <cylinder radius="0.1" length="0.05"/>
        </geometry>
        <origin xyz="0 0 0.025" rpy="0 0 0"/>
    </visual>
    <inertial>
        <mass value="1.0"/>
        <origin xyz="0 0 0.025" rpy="0 0 0"/>
        <inertia ixx="0.01" ixy="0.0" ixz="0.0"
                iyy="0.01" iyz="0.0"
                izz="0.01"/>
    </inertial>
  </link>

  <joint name="z_lift_joint" type="prismatic">
    <parent link="world"/>
    <child link="z_lift_link"/>
    <origin xyz="0 0 0" rpy="0 0 0"/>
    <axis xyz="0 0 1"/>
    <limit lower="0.0" upper="1.0" effort="100" velocity="0.2"/>
  </joint>

  <!-- Transmission -->
  <transmission name="z_lift_trans">
    <type>transmission_interface/SimpleTransmission</type>
    <joint name="z_lift_joint">
      <hardwareInterface>position</hardwareInterface>
    </joint>
    <actuator name="z_lift_motor">
      <mechanicalReduction>1.0</mechanicalReduction>
    </actuator>
  </transmission>


  <!-- Arm -->
  <xacro:ur_robot
    name="$(arg name)"
    tf_prefix="$(arg tf_prefix)"
    parent="z_lift_link"
    joint_limits_parameters_file="$(arg joint_limit_params)"
    kinematics_parameters_file="$(arg kinematics_params)"
    physical_parameters_file="$(arg physical_params)"
    visual_parameters_file="$(arg visual_params)"
    safety_limits="$(arg safety_limits)"
    safety_pos_margin="$(arg safety_pos_margin)"
    safety_k_position="$(arg safety_k_position)"
    force_abs_paths="true">
    <origin xyz="0 0 0" rpy="0 0 0"/>
  </xacro:ur_robot>

  <!-- Gazebo Plugin -->
  <gazebo>
    <plugin filename="libgz_ros2_control-system.so" name="gz_ros2_control::GazeboSimROS2ControlPlugin">
      <parameters>$(find ur10e_mod)/config/ur_controllers_with_z_lift.yaml</parameters>
    </plugin>
  </gazebo>

  <gazebo reference="world">
  </gazebo>
  <gazebo>
    <plugin filename="gz_ros2_control-system" name="gz_ros2_control::GazeboSimROS2ControlPlugin">
      <parameters>$(arg simulation_controllers)</parameters>
      <ros>
        <namespace>$(arg ros_namespace)</namespace>
      </ros>
    </plugin>
  </gazebo>

  <!-- ros2_control block -->
  <xacro:ur_ros2_control
    name="$(arg name)"
    tf_prefix="$(arg tf_prefix)"
    transmission_hw_interface="$(arg transmission_hw_interface)"
    initial_positions="${dict(z_lift_joint=0.5,shoulder_pan_joint=0.0,shoulder_lift_joint=-1.57,elbow_joint=0.0,wrist_1_joint=-1.57,wrist_2_joint=0.0,wrist_3_joint=0.0)}"
  />

</robot>